Workbook

Sheet Anleitung
B1: Nasdaq 10:00-Reversal: Trading-Journal (5-Minuten-Chart)
B3: Die Strategie
B4: 1. Morgen-Bewegung: Wie weit läuft der Nasdaq (NQ/MNQ oder QQQ) von 09:30 bis 10:00 New Yorker Zeit (in Deutschland meist 15:30 bis 16:00)?
B5: 2. Ist die Bewegung groß genug (Einstellungen: Mindestbewegung), wird um 10:00 dagegen gehandelt: nach einem Anstieg Short, nach einem Fall Long.
B6: 3. Einstieg: Schließt die 10:05- oder 10:10-Kerze unter dem Tief (bei Short) bzw. über dem Hoch (bei Long) der 10:00-Kerze, wird zum Open der nächsten Kerze eingestiegen.
B7: 4. Stop: Tageshoch (Short) bzw. Tagestief (Long) bis zum Einstieg. Ziel: 2 × Risiko. Spätestens um 11:30 wird geschlossen.
B9: So füllst du das Journal aus (Blatt „Journal“)
B10: • Nur die gelben Zellen mit blauer Schrift ausfüllen. Graue Spalten rechnet Excel selbst.
B11: • Pro Handelstag eine Zeile. Die Daten des letzten Monats sind schon eingetragen; weitere Tage einfach unten anhängen.
B12: • Kurse aus dem 5-Minuten-Chart ablesen (TradingView, Broker). Alle Kurse vom selben Instrument nehmen.
B13: • Gibt es keinen Ausbruch bis 10:15, bleibt „Einstiegskurs“ leer. Der Tag zählt dann als „kein Signal“.
B14: • Nach dem Eintragen des Einstiegs zeigt Excel Stop und Ziel. Im Chart nachsehen, was zuerst erreicht wurde, und bei „Ergebnis“ Ziel, Stop oder Zeit wählen. Bei Zeit den Kurs um 11:30 eintragen.
... B24: Kein Anlageratschlag. Ein Monat (ca. 20 Handelstage) zeigt, wie es zuletzt lief, beweist aber keinen dauerhaften Vorteil. Für eine belastbare Aussage braucht es mehrere Jahre Daten (siehe backtest/README.md).

Sheet Journal
A1: Journal: eine Zeile pro Handelstag
A2: Gelb = selbst eintragen (aus dem 5-Minuten-Chart). Grau = rechnet Excel. Zeiten = New York (ET).
A3: EINGABE | L3: BERECHNUNG
A4: Datum | B4: Open 09:30 | C4: Close 09:55-Kerze | D4: Tageshoch bis Einstieg | E4: Tagestief bis Einstieg | F4: Hoch 10:00-Kerze | G4: Tief 10:00-Kerze | H4: Einstiegskurs | I4: Ergebnis | J4: Kurs 11:30 | K4: Notiz | L4: Morgen-Bewegung | M4: Richtung | N4: Status | O4: Stop | P4: Risiko (Pkt) | Q4: Ziel | R4: Exitkurs | S4: Punkte netto | T4: R | U4: Gewinn/Verlust | V4: Kumuliert | W4: Höchststand | X4: Drawdown | Y4: Hinweis | Z4: Wochentag
A5: 46287 | L5: =IF(OR(B5="",C5=""),"",(C5-B5)/B5) | M5: =IF(L5="","",IF(ABS(L5)<MinDrive,"kein Trade",IF(L5>0,"Short","Long"))) | N5: =IF(OR(M5="",M5="kein Trade"),"",IF(H5="","kein Signal","Trade")) | O5: =IF(N5<>"Trade","",IF(M5="Short",D5,E5)) | P5: =IF(N5<>"Trade","",ABS(H5-O5)) | Q5: =IF(N5<>"Trade","",H5+IF(M5="Long",1,-1)*ZielR*P5) | R5: =IF(OR(N5<>"Trade",I5=""),"",IF(I5="Ziel",Q5,IF(I5="Stop",O5,IF(J5="","",J5)))) | S5: =IF(R5="","",(R5-H5)*IF(M5="Long",1,-1)-2*Slippage) | T5: =IF(OR(S5="",P5=0),"",S5/P5) | U5: =IF(S5="","",S5*Punktwert*Kontrakte-Kommission*Kontrakte) | V5: =IF(U5="","",SUM($U$5:U5)) | W5: =IF(V5="","",MAX(0,MAX($V$5:V5))) | X5: =IF(V5="","",V5-W5) | Y5: =IF(N5<>"Trade","",IF(P5=0,"Stop = Einstieg?",IF(I5="","Ergebnis eintragen",IF(AND(I5="Zeit",J5=""),"Kurs 11:30 fehlt",IF(OR(AND(M5="Short",H5>F5),AND(M5="Long",H5<G5)),"Einstieg prüfen","ok"))))) | Z5: =IF(A5="","",WEEKDAY(A5,2)) -> 2
A6: 46288 | L6: =IF(OR(B6="",C6=""),"",(C6-B6)/B6) | M6: =IF(L6="","",IF(ABS(L6)<MinDrive,"kein Trade",IF(L6>0,"Short","Long"))) | N6: =IF(OR(M6="",M6="kein Trade"),"",IF(H6="","kein Signal","Trade")) | O6: =IF(N6<>"Trade","",IF(M6="Short",D6,E6)) | P6: =IF(N6<>"Trade","",ABS(H6-O6)) | Q6: =IF(N6<>"Trade","",H6+IF(M6="Long",1,-1)*ZielR*P6) | R6: =IF(OR(N6<>"Trade",I6=""),"",IF(I6="Ziel",Q6,IF(I6="Stop",O6,IF(J6="","",J6)))) | S6: =IF(R6="","",(R6-H6)*IF(M6="Long",1,-1)-2*Slippage) | T6: =IF(OR(S6="",P6=0),"",S6/P6) | U6: =IF(S6="","",S6*Punktwert*Kontrakte-Kommission*Kontrakte) | V6: =IF(U6="","",SUM($U$5:U6)) | W6: =IF(V6="","",MAX(0,MAX($V$5:V6))) | X6: =IF(V6="","",V6-W6) | Y6: =IF(N6<>"Trade","",IF(P6=0,"Stop = Einstieg?",IF(I6="","Ergebnis eintragen",IF(AND(I6="Zeit",J6=""),"Kurs 11:30 fehlt",IF(OR(AND(M6="Short",H6>F6),AND(M6="Long",H6<G6)),"Einstieg prüfen","ok"))))) | Z6: =IF(A6="","",WEEKDAY(A6,2)) -> 3
A7: 46289 | L7: =IF(OR(B7="",C7=""),"",(C7-B7)/B7) | M7: =IF(L7="","",IF(ABS(L7)<MinDrive,"kein Trade",IF(L7>0,"Short","Long"))) | N7: =IF(OR(M7="",M7="kein Trade"),"",IF(H7="","kein Signal","Trade")) | O7: =IF(N7<>"Trade","",IF(M7="Short",D7,E7)) | P7: =IF(N7<>"Trade","",ABS(H7-O7)) | Q7: =IF(N7<>"Trade","",H7+IF(M7="Long",1,-1)*ZielR*P7) | R7: =IF(OR(N7<>"Trade",I7=""),"",IF(I7="Ziel",Q7,IF(I7="Stop",O7,IF(J7="","",J7)))) | S7: =IF(R7="","",(R7-H7)*IF(M7="Long",1,-1)-2*Slippage) | T7: =IF(OR(S7="",P7=0),"",S7/P7) | U7: =IF(S7="","",S7*Punktwert*Kontrakte-Kommission*Kontrakte) | V7: =IF(U7="","",SUM($U$5:U7)) | W7: =IF(V7="","",MAX(0,MAX($V$5:V7))) | X7: =IF(V7="","",V7-W7) | Y7: =IF(N7<>"Trade","",IF(P7=0,"Stop = Einstieg?",IF(I7="","Ergebnis eintragen",IF(AND(I7="Zeit",J7=""),"Kurs 11:30 fehlt",IF(OR(AND(M7="Short",H7>F7),AND(M7="Long",H7<G7)),"Einstieg prüfen","ok"))))) | Z7: =IF(A7="","",WEEKDAY(A7,2)) -> 4
A8: 46290 | L8: =IF(OR(B8="",C8=""),"",(C8-B8)/B8) | M8: =IF(L8="","",IF(ABS(L8)<MinDrive,"kein Trade",IF(L8>0,"Short","Long"))) | N8: =IF(OR(M8="",M8="kein Trade"),"",IF(H8="","kein Signal","Trade")) | O8: =IF(N8<>"Trade","",IF(M8="Short",D8,E8)) | P8: =IF(N8<>"Trade","",ABS(H8-O8)) | Q8: =IF(N8<>"Trade","",H8+IF(M8="Long",1,-1)*ZielR*P8) | R8: =IF(OR(N8<>"Trade",I8=""),"",IF(I8="Ziel",Q8,IF(I8="Stop",O8,IF(J8="","",J8)))) | S8: =IF(R8="","",(R8-H8)*IF(M8="Long",1,-1)-2*Slippage) | T8: =IF(OR(S8="",P8=0),"",S8/P8) | U8: =IF(S8="","",S8*Punktwert*Kontrakte-Kommission*Kontrakte) | V8: =IF(U8="","",SUM($U$5:U8)) | W8: =IF(V8="","",MAX(0,MAX($V$5:V8))) | X8: =IF(V8="","",V8-W8) | Y8: =IF(N8<>"Trade","",IF(P8=0,"Stop = Einstieg?",IF(I8="","Ergebnis eintragen",IF(AND(I8="Zeit",J8=""),"Kurs 11:30 fehlt",IF(OR(AND(M8="Short",H8>F8),AND(M8="Long",H8<G8)),"Einstieg prüfen","ok"))))) | Z8: =IF(A8="","",WEEKDAY(A8,2)) -> 5
A9: 46293 | L9: =IF(OR(B9="",C9=""),"",(C9-B9)/B9) | M9: =IF(L9="","",IF(ABS(L9)<MinDrive,"kein Trade",IF(L9>0,"Short","Long"))) | N9: =IF(OR(M9="",M9="kein Trade"),"",IF(H9="","kein Signal","Trade")) | O9: =IF(N9<>"Trade","",IF(M9="Short",D9,E9)) | P9: =IF(N9<>"Trade","",ABS(H9-O9)) | Q9: =IF(N9<>"Trade","",H9+IF(M9="Long",1,-1)*ZielR*P9) | R9: =IF(OR(N9<>"Trade",I9=""),"",IF(I9="Ziel",Q9,IF(I9="Stop",O9,IF(J9="","",J9)))) | S9: =IF(R9="","",(R9-H9)*IF(M9="Long",1,-1)-2*Slippage) | T9: =IF(OR(S9="",P9=0),"",S9/P9) | U9: =IF(S9="","",S9*Punktwert*Kontrakte-Kommission*Kontrakte) | V9: =IF(U9="","",SUM($U$5:U9)) | W9: =IF(V9="","",MAX(0,MAX($V$5:V9))) | X9: =IF(V9="","",V9-W9) | Y9: =IF(N9<>"Trade","",IF(P9=0,"Stop = Einstieg?",IF(I9="","Ergebnis eintragen",IF(AND(I9="Zeit",J9=""),"Kurs 11:30 fehlt",IF(OR(AND(M9="Short",H9>F9),AND(M9="Long",H9<G9)),"Einstieg prüfen","ok"))))) | Z9: =IF(A9="","",WEEKDAY(A9,2)) -> 1
A10: 46294 | L10: =IF(OR(B10="",C10=""),"",(C10-B10)/B10) | M10: =IF(L10="","",IF(ABS(L10)<MinDrive,"kein Trade",IF(L10>0,"Short","Long"))) | N10: =IF(OR(M10="",M10="kein Trade"),"",IF(H10="","kein Signal","Trade")) | O10: =IF(N10<>"Trade","",IF(M10="Short",D10,E10)) | P10: =IF(N10<>"Trade","",ABS(H10-O10)) | Q10: =IF(N10<>"Trade","",H10+IF(M10="Long",1,-1)*ZielR*P10) | R10: =IF(OR(N10<>"Trade",I10=""),"",IF(I10="Ziel",Q10,IF(I10="Stop",O10,IF(J10="","",J10)))) | S10: =IF(R10="","",(R10-H10)*IF(M10="Long",1,-1)-2*Slippage) | T10: =IF(OR(S10="",P10=0),"",S10/P10) | U10: =IF(S10="","",S10*Punktwert*Kontrakte-Kommission*Kontrakte) | V10: =IF(U10="","",SUM($U$5:U10)) | W10: =IF(V10="","",MAX(0,MAX($V$5:V10))) | X10: =IF(V10="","",V10-W10) | Y10: =IF(N10<>"Trade","",IF(P10=0,"Stop = Einstieg?",IF(I10="","Ergebnis eintragen",IF(AND(I10="Zeit",J10=""),"Kurs 11:30 fehlt",IF(OR(AND(M10="Short",H10>F10),AND(M10="Long",H10<G10)),"Einstieg prüfen","ok"))))) | Z10: =IF(A10="","",WEEKDAY(A10,2)) -> 2
A11: 46295 | L11: =IF(OR(B11="",C11=""),"",(C11-B11)/B11) | M11: =IF(L11="","",IF(ABS(L11)<MinDrive,"kein Trade",IF(L11>0,"Short","Long"))) | N11: =IF(OR(M11="",M11="kein Trade"),"",IF(H11="","kein Signal","Trade")) | O11: =IF(N11<>"Trade","",IF(M11="Short",D11,E11)) | P11: =IF(N11<>"Trade","",ABS(H11-O11)) | Q11: =IF(N11<>"Trade","",H11+IF(M11="Long",1,-1)*ZielR*P11) | R11: =IF(OR(N11<>"Trade",I11=""),"",IF(I11="Ziel",Q11,IF(I11="Stop",O11,IF(J11="","",J11)))) | S11: =IF(R11="","",(R11-H11)*IF(M11="Long",1,-1)-2*Slippage) | T11: =IF(OR(S11="",P11=0),"",S11/P11) | U11: =IF(S11="","",S11*Punktwert*Kontrakte-Kommission*Kontrakte) | V11: =IF(U11="","",SUM($U$5:U11)) | W11: =IF(V11="","",MAX(0,MAX($V$5:V11))) | X11: =IF(V11="","",V11-W11) | Y11: =IF(N11<>"Trade","",IF(P11=0,"Stop = Einstieg?",IF(I11="","Ergebnis eintragen",IF(AND(I11="Zeit",J11=""),"Kurs 11:30 fehlt",IF(OR(AND(M11="Short",H11>F11),AND(M11="Long",H11<G11)),"Einstieg prüfen","ok"))))) | Z11: =IF(A11="","",WEEKDAY(A11,2)) -> 3
A12: 46296 | L12: =IF(OR(B12="",C12=""),"",(C12-B12)/B12) | M12: =IF(L12="","",IF(ABS(L12)<MinDrive,"kein Trade",IF(L12>0,"Short","Long"))) | N12: =IF(OR(M12="",M12="kein Trade"),"",IF(H12="","kein Signal","Trade")) | O12: =IF(N12<>"Trade","",IF(M12="Short",D12,E12)) | P12: =IF(N12<>"Trade","",ABS(H12-O12)) | Q12: =IF(N12<>"Trade","",H12+IF(M12="Long",1,-1)*ZielR*P12) | R12: =IF(OR(N12<>"Trade",I12=""),"",IF(I12="Ziel",Q12,IF(I12="Stop",O12,IF(J12="","",J12)))) | S12: =IF(R12="","",(R12-H12)*IF(M12="Long",1,-1)-2*Slippage) | T12: =IF(OR(S12="",P12=0),"",S12/P12) | U12: =IF(S12="","",S12*Punktwert*Kontrakte-Kommission*Kontrakte) | V12: =IF(U12="","",SUM($U$5:U12)) | W12: =IF(V12="","",MAX(0,MAX($V$5:V12))) | X12: =IF(V12="","",V12-W12) | Y12: =IF(N12<>"Trade","",IF(P12=0,"Stop = Einstieg?",IF(I12="","Ergebnis eintragen",IF(AND(I12="Zeit",J12=""),"Kurs 11:30 fehlt",IF(OR(AND(M12="Short",H12>F12),AND(M12="Long",H12<G12)),"Einstieg prüfen","ok"))))) | Z12: =IF(A12="","",WEEKDAY(A12,2)) -> 4
A13: 46297 | L13: =IF(OR(B13="",C13=""),"",(C13-B13)/B13) | M13: =IF(L13="","",IF(ABS(L13)<MinDrive,"kein Trade",IF(L13>0,"Short","Long"))) | N13: =IF(OR(M13="",M13="kein Trade"),"",IF(H13="","kein Signal","Trade")) | O13: =IF(N13<>"Trade","",IF(M13="Short",D13,E13)) | P13: =IF(N13<>"Trade","",ABS(H13-O13)) | Q13: =IF(N13<>"Trade","",H13+IF(M13="Long",1,-1)*ZielR*P13) | R13: =IF(OR(N13<>"Trade",I13=""),"",IF(I13="Ziel",Q13,IF(I13="Stop",O13,IF(J13="","",J13)))) | S13: =IF(R13="","",(R13-H13)*IF(M13="Long",1,-1)-2*Slippage) | T13: =IF(OR(S13="",P13=0),"",S13/P13) | U13: =IF(S13="","",S13*Punktwert*Kontrakte-Kommission*Kontrakte) | V13: =IF(U13="","",SUM($U$5:U13)) | W13: =IF(V13="","",MAX(0,MAX($V$5:V13))) | X13: =IF(V13="","",V13-W13) | Y13: =IF(N13<>"Trade","",IF(P13=0,"Stop = Einstieg?",IF(I13="","Ergebnis eintragen",IF(AND(I13="Zeit",J13=""),"Kurs 11:30 fehlt",IF(OR(AND(M13="Short",H13>F13),AND(M13="Long",H13<G13)),"Einstieg prüfen","ok"))))) | Z13: =IF(A13="","",WEEKDAY(A13,2)) -> 5
A14: 46300 | L14: =IF(OR(B14="",C14=""),"",(C14-B14)/B14) | M14: =IF(L14="","",IF(ABS(L14)<MinDrive,"kein Trade",IF(L14>0,"Short","Long"))) | N14: =IF(OR(M14="",M14="kein Trade"),"",IF(H14="","kein Signal","Trade")) | O14: =IF(N14<>"Trade","",IF(M14="Short",D14,E14)) | P14: =IF(N14<>"Trade","",ABS(H14-O14)) | Q14: =IF(N14<>"Trade","",H14+IF(M14="Long",1,-1)*ZielR*P14) | R14: =IF(OR(N14<>"Trade",I14=""),"",IF(I14="Ziel",Q14,IF(I14="Stop",O14,IF(J14="","",J14)))) | S14: =IF(R14="","",(R14-H14)*IF(M14="Long",1,-1)-2*Slippage) | T14: =IF(OR(S14="",P14=0),"",S14/P14) | U14: =IF(S14="","",S14*Punktwert*Kontrakte-Kommission*Kontrakte) | V14: =IF(U14="","",SUM($U$5:U14)) | W14: =IF(V14="","",MAX(0,MAX($V$5:V14))) | X14: =IF(V14="","",V14-W14) | Y14: =IF(N14<>"Trade","",IF(P14=0,"Stop = Einstieg?",IF(I14="","Ergebnis eintragen",IF(AND(I14="Zeit",J14=""),"Kurs 11:30 fehlt",IF(OR(AND(M14="Short",H14>F14),AND(M14="Long",H14<G14)),"Einstieg prüfen","ok"))))) | Z14: =IF(A14="","",WEEKDAY(A14,2)) -> 1
A15: 46301 | L15: =IF(OR(B15="",C15=""),"",(C15-B15)/B15) | M15: =IF(L15="","",IF(ABS(L15)<MinDrive,"kein Trade",IF(L15>0,"Short","Long"))) | N15: =IF(OR(M15="",M15="kein Trade"),"",IF(H15="","kein Signal","Trade")) | O15: =IF(N15<>"Trade","",IF(M15="Short",D15,E15)) | P15: =IF(N15<>"Trade","",ABS(H15-O15)) | Q15: =IF(N15<>"Trade","",H15+IF(M15="Long",1,-1)*ZielR*P15) | R15: =IF(OR(N15<>"Trade",I15=""),"",IF(I15="Ziel",Q15,IF(I15="Stop",O15,IF(J15="","",J15)))) | S15: =IF(R15="","",(R15-H15)*IF(M15="Long",1,-1)-2*Slippage) | T15: =IF(OR(S15="",P15=0),"",S15/P15) | U15: =IF(S15="","",S15*Punktwert*Kontrakte-Kommission*Kontrakte) | V15: =IF(U15="","",SUM($U$5:U15)) | W15: =IF(V15="","",MAX(0,MAX($V$5:V15))) | X15: =IF(V15="","",V15-W15) | Y15: =IF(N15<>"Trade","",IF(P15=0,"Stop = Einstieg?",IF(I15="","Ergebnis eintragen",IF(AND(I15="Zeit",J15=""),"Kurs 11:30 fehlt",IF(OR(AND(M15="Short",H15>F15),AND(M15="Long",H15<G15)),"Einstieg prüfen","ok"))))) | Z15: =IF(A15="","",WEEKDAY(A15,2)) -> 2
A16: 46302 | L16: =IF(OR(B16="",C16=""),"",(C16-B16)/B16) | M16: =IF(L16="","",IF(ABS(L16)<MinDrive,"kein Trade",IF(L16>0,"Short","Long"))) | N16: =IF(OR(M16="",M16="kein Trade"),"",IF(H16="","kein Signal","Trade")) | O16: =IF(N16<>"Trade","",IF(M16="Short",D16,E16)) | P16: =IF(N16<>"Trade","",ABS(H16-O16)) | Q16: =IF(N16<>"Trade","",H16+IF(M16="Long",1,-1)*ZielR*P16) | R16: =IF(OR(N16<>"Trade",I16=""),"",IF(I16="Ziel",Q16,IF(I16="Stop",O16,IF(J16="","",J16)))) | S16: =IF(R16="","",(R16-H16)*IF(M16="Long",1,-1)-2*Slippage) | T16: =IF(OR(S16="",P16=0),"",S16/P16) | U16: =IF(S16="","",S16*Punktwert*Kontrakte-Kommission*Kontrakte) | V16: =IF(U16="","",SUM($U$5:U16)) | W16: =IF(V16="","",MAX(0,MAX($V$5:V16))) | X16: =IF(V16="","",V16-W16) | Y16: =IF(N16<>"Trade","",IF(P16=0,"Stop = Einstieg?",IF(I16="","Ergebnis eintragen",IF(AND(I16="Zeit",J16=""),"Kurs 11:30 fehlt",IF(OR(AND(M16="Short",H16>F16),AND(M16="Long",H16<G16)),"Einstieg prüfen","ok"))))) | Z16: =IF(A16="","",WEEKDAY(A16,2)) -> 3
... A26: 46316 | L26: =IF(OR(B26="",C26=""),"",(C26-B26)/B26) | M26: =IF(L26="","",IF(ABS(L26)<MinDrive,"kein Trade",IF(L26>0,"Short","Long"))) | N26: =IF(OR(M26="",M26="kein Trade"),"",IF(H26="","kein Signal","Trade")) | O26: =IF(N26<>"Trade","",IF(M26="Short",D26,E26)) | P26: =IF(N26<>"Trade","",ABS(H26-O26)) | Q26: =IF(N26<>"Trade","",H26+IF(M26="Long",1,-1)*ZielR*P26) | R26: =IF(OR(N26<>"Trade",I26=""),"",IF(I26="Ziel",Q26,IF(I26="Stop",O26,IF(J26="","",J26)))) | S26: =IF(R26="","",(R26-H26)*IF(M26="Long",1,-1)-2*Slippage) | T26: =IF(OR(S26="",P26=0),"",S26/P26) | U26: =IF(S26="","",S26*Punktwert*Kontrakte-Kommission*Kontrakte) | V26: =IF(U26="","",SUM($U$5:U26)) | W26: =IF(V26="","",MAX(0,MAX($V$5:V26))) | X26: =IF(V26="","",V26-W26) | Y26: =IF(N26<>"Trade","",IF(P26=0,"Stop = Einstieg?",IF(I26="","Ergebnis eintragen",IF(AND(I26="Zeit",J26=""),"Kurs 11:30 fehlt",IF(OR(AND(M26="Short",H26>F26),AND(M26="Long",H26<G26)),"Einstieg prüfen","ok"))))) | Z26: =IF(A26="","",WEEKDAY(A26,2)) -> 3
L27: =IF(OR(B27="",C27=""),"",(C27-B27)/B27) | M27: =IF(L27="","",IF(ABS(L27)<MinDrive,"kein Trade",IF(L27>0,"Short","Long"))) | N27: =IF(OR(M27="",M27="kein Trade"),"",IF(H27="","kein Signal","Trade")) | O27: =IF(N27<>"Trade","",IF(M27="Short",D27,E27)) | P27: =IF(N27<>"Trade","",ABS(H27-O27)) | Q27: =IF(N27<>"Trade","",H27+IF(M27="Long",1,-1)*ZielR*P27) | R27: =IF(OR(N27<>"Trade",I27=""),"",IF(I27="Ziel",Q27,IF(I27="Stop",O27,IF(J27="","",J27)))) | S27: =IF(R27="","",(R27-H27)*IF(M27="Long",1,-1)-2*Slippage) | T27: =IF(OR(S27="",P27=0),"",S27/P27) | U27: =IF(S27="","",S27*Punktwert*Kontrakte-Kommission*Kontrakte) | V27: =IF(U27="","",SUM($U$5:U27)) | W27: =IF(V27="","",MAX(0,MAX($V$5:V27))) | X27: =IF(V27="","",V27-W27) | Y27: =IF(N27<>"Trade","",IF(P27=0,"Stop = Einstieg?",IF(I27="","Ergebnis eintragen",IF(AND(I27="Zeit",J27=""),"Kurs 11:30 fehlt",IF(OR(AND(M27="Short",H27>F27),AND(M27="Long",H27<G27)),"Einstieg prüfen","ok"))))) | Z27: =IF(A27="","",WEEKDAY(A27,2))
L28: =IF(OR(B28="",C28=""),"",(C28-B28)/B28) | M28: =IF(L28="","",IF(ABS(L28)<MinDrive,"kein Trade",IF(L28>0,"Short","Long"))) | N28: =IF(OR(M28="",M28="kein Trade"),"",IF(H28="","kein Signal","Trade")) | O28: =IF(N28<>"Trade","",IF(M28="Short",D28,E28)) | P28: =IF(N28<>"Trade","",ABS(H28-O28)) | Q28: =IF(N28<>"Trade","",H28+IF(M28="Long",1,-1)*ZielR*P28) | R28: =IF(OR(N28<>"Trade",I28=""),"",IF(I28="Ziel",Q28,IF(I28="Stop",O28,IF(J28="","",J28)))) | S28: =IF(R28="","",(R28-H28)*IF(M28="Long",1,-1)-2*Slippage) | T28: =IF(OR(S28="",P28=0),"",S28/P28) | U28: =IF(S28="","",S28*Punktwert*Kontrakte-Kommission*Kontrakte) | V28: =IF(U28="","",SUM($U$5:U28)) | W28: =IF(V28="","",MAX(0,MAX($V$5:V28))) | X28: =IF(V28="","",V28-W28) | Y28: =IF(N28<>"Trade","",IF(P28=0,"Stop = Einstieg?",IF(I28="","Ergebnis eintragen",IF(AND(I28="Zeit",J28=""),"Kurs 11:30 fehlt",IF(OR(AND(M28="Short",H28>F28),AND(M28="Long",H28<G28)),"Einstieg prüfen","ok"))))) | Z28: =IF(A28="","",WEEKDAY(A28,2))
L29: =IF(OR(B29="",C29=""),"",(C29-B29)/B29) | M29: =IF(L29="","",IF(ABS(L29)<MinDrive,"kein Trade",IF(L29>0,"Short","Long"))) | N29: =IF(OR(M29="",M29="kein Trade"),"",IF(H29="","kein Signal","Trade")) | O29: =IF(N29<>"Trade","",IF(M29="Short",D29,E29)) | P29: =IF(N29<>"Trade","",ABS(H29-O29)) | Q29: =IF(N29<>"Trade","",H29+IF(M29="Long",1,-1)*ZielR*P29) | R29: =IF(OR(N29<>"Trade",I29=""),"",IF(I29="Ziel",Q29,IF(I29="Stop",O29,IF(J29="","",J29)))) | S29: =IF(R29="","",(R29-H29)*IF(M29="Long",1,-1)-2*Slippage) | T29: =IF(OR(S29="",P29=0),"",S29/P29) | U29: =IF(S29="","",S29*Punktwert*Kontrakte-Kommission*Kontrakte) | V29: =IF(U29="","",SUM($U$5:U29)) | W29: =IF(V29="","",MAX(0,MAX($V$5:V29))) | X29: =IF(V29="","",V29-W29) | Y29: =IF(N29<>"Trade","",IF(P29=0,"Stop = Einstieg?",IF(I29="","Ergebnis eintragen",IF(AND(I29="Zeit",J29=""),"Kurs 11:30 fehlt",IF(OR(AND(M29="Short",H29>F29),AND(M29="Long",H29<G29)),"Einstieg prüfen","ok"))))) | Z29: =IF(A29="","",WEEKDAY(A29,2))
L30: =IF(OR(B30="",C30=""),"",(C30-B30)/B30) | M30: =IF(L30="","",IF(ABS(L30)<MinDrive,"kein Trade",IF(L30>0,"Short","Long"))) | N30: =IF(OR(M30="",M30="kein Trade"),"",IF(H30="","kein Signal","Trade")) | O30: =IF(N30<>"Trade","",IF(M30="Short",D30,E30)) | P30: =IF(N30<>"Trade","",ABS(H30-O30)) | Q30: =IF(N30<>"Trade","",H30+IF(M30="Long",1,-1)*ZielR*P30) | R30: =IF(OR(N30<>"Trade",I30=""),"",IF(I30="Ziel",Q30,IF(I30="Stop",O30,IF(J30="","",J30)))) | S30: =IF(R30="","",(R30-H30)*IF(M30="Long",1,-1)-2*Slippage) | T30: =IF(OR(S30="",P30=0),"",S30/P30) | U30: =IF(S30="","",S30*Punktwert*Kontrakte-Kommission*Kontrakte) | V30: =IF(U30="","",SUM($U$5:U30)) | W30: =IF(V30="","",MAX(0,MAX($V$5:V30))) | X30: =IF(V30="","",V30-W30) | Y30: =IF(N30<>"Trade","",IF(P30=0,"Stop = Einstieg?",IF(I30="","Ergebnis eintragen",IF(AND(I30="Zeit",J30=""),"Kurs 11:30 fehlt",IF(OR(AND(M30="Short",H30>F30),AND(M30="Long",H30<G30)),"Einstieg prüfen","ok"))))) | Z30: =IF(A30="","",WEEKDAY(A30,2))
L31: =IF(OR(B31="",C31=""),"",(C31-B31)/B31) | M31: =IF(L31="","",IF(ABS(L31)<MinDrive,"kein Trade",IF(L31>0,"Short","Long"))) | N31: =IF(OR(M31="",M31="kein Trade"),"",IF(H31="","kein Signal","Trade")) | O31: =IF(N31<>"Trade","",IF(M31="Short",D31,E31)) | P31: =IF(N31<>"Trade","",ABS(H31-O31)) | Q31: =IF(N31<>"Trade","",H31+IF(M31="Long",1,-1)*ZielR*P31) | R31: =IF(OR(N31<>"Trade",I31=""),"",IF(I31="Ziel",Q31,IF(I31="Stop",O31,IF(J31="","",J31)))) | S31: =IF(R31="","",(R31-H31)*IF(M31="Long",1,-1)-2*Slippage) | T31: =IF(OR(S31="",P31=0),"",S31/P31) | U31: =IF(S31="","",S31*Punktwert*Kontrakte-Kommission*Kontrakte) | V31: =IF(U31="","",SUM($U$5:U31)) | W31: =IF(V31="","",MAX(0,MAX($V$5:V31))) | X31: =IF(V31="","",V31-W31) | Y31: =IF(N31<>"Trade","",IF(P31=0,"Stop = Einstieg?",IF(I31="","Ergebnis eintragen",IF(AND(I31="Zeit",J31=""),"Kurs 11:30 fehlt",IF(OR(AND(M31="Short",H31>F31),AND(M31="Long",H31<G31)),"Einstieg prüfen","ok"))))) | Z31: =IF(A31="","",WEEKDAY(A31,2))
L32: =IF(OR(B32="",C32=""),"",(C32-B32)/B32) | M32: =IF(L32="","",IF(ABS(L32)<MinDrive,"kein Trade",IF(L32>0,"Short","Long"))) | N32: =IF(OR(M32="",M32="kein Trade"),"",IF(H32="","kein Signal","Trade")) | O32: =IF(N32<>"Trade","",IF(M32="Short",D32,E32)) | P32: =IF(N32<>"Trade","",ABS(H32-O32)) | Q32: =IF(N32<>"Trade","",H32+IF(M32="Long",1,-1)*ZielR*P32) | R32: =IF(OR(N32<>"Trade",I32=""),"",IF(I32="Ziel",Q32,IF(I32="Stop",O32,IF(J32="","",J32)))) | S32: =IF(R32="","",(R32-H32)*IF(M32="Long",1,-1)-2*Slippage) | T32: =IF(OR(S32="",P32=0),"",S32/P32) | U32: =IF(S32="","",S32*Punktwert*Kontrakte-Kommission*Kontrakte) | V32: =IF(U32="","",SUM($U$5:U32)) | W32: =IF(V32="","",MAX(0,MAX($V$5:V32))) | X32: =IF(V32="","",V32-W32) | Y32: =IF(N32<>"Trade","",IF(P32=0,"Stop = Einstieg?",IF(I32="","Ergebnis eintragen",IF(AND(I32="Zeit",J32=""),"Kurs 11:30 fehlt",IF(OR(AND(M32="Short",H32>F32),AND(M32="Long",H32<G32)),"Einstieg prüfen","ok"))))) | Z32: =IF(A32="","",WEEKDAY(A32,2))
L33: =IF(OR(B33="",C33=""),"",(C33-B33)/B33) | M33: =IF(L33="","",IF(ABS(L33)<MinDrive,"kein Trade",IF(L33>0,"Short","Long"))) | N33: =IF(OR(M33="",M33="kein Trade"),"",IF(H33="","kein Signal","Trade")) | O33: =IF(N33<>"Trade","",IF(M33="Short",D33,E33)) | P33: =IF(N33<>"Trade","",ABS(H33-O33)) | Q33: =IF(N33<>"Trade","",H33+IF(M33="Long",1,-1)*ZielR*P33) | R33: =IF(OR(N33<>"Trade",I33=""),"",IF(I33="Ziel",Q33,IF(I33="Stop",O33,IF(J33="","",J33)))) | S33: =IF(R33="","",(R33-H33)*IF(M33="Long",1,-1)-2*Slippage) | T33: =IF(OR(S33="",P33=0),"",S33/P33) | U33: =IF(S33="","",S33*Punktwert*Kontrakte-Kommission*Kontrakte) | V33: =IF(U33="","",SUM($U$5:U33)) | W33: =IF(V33="","",MAX(0,MAX($V$5:V33))) | X33: =IF(V33="","",V33-W33) | Y33: =IF(N33<>"Trade","",IF(P33=0,"Stop = Einstieg?",IF(I33="","Ergebnis eintragen",IF(AND(I33="Zeit",J33=""),"Kurs 11:30 fehlt",IF(OR(AND(M33="Short",H33>F33),AND(M33="Long",H33<G33)),"Einstieg prüfen","ok"))))) | Z33: =IF(A33="","",WEEKDAY(A33,2))
L34: =IF(OR(B34="",C34=""),"",(C34-B34)/B34) | M34: =IF(L34="","",IF(ABS(L34)<MinDrive,"kein Trade",IF(L34>0,"Short","Long"))) | N34: =IF(OR(M34="",M34="kein Trade"),"",IF(H34="","kein Signal","Trade")) | O34: =IF(N34<>"Trade","",IF(M34="Short",D34,E34)) | P34: =IF(N34<>"Trade","",ABS(H34-O34)) | Q34: =IF(N34<>"Trade","",H34+IF(M34="Long",1,-1)*ZielR*P34) | R34: =IF(OR(N34<>"Trade",I34=""),"",IF(I34="Ziel",Q34,IF(I34="Stop",O34,IF(J34="","",J34)))) | S34: =IF(R34="","",(R34-H34)*IF(M34="Long",1,-1)-2*Slippage) | T34: =IF(OR(S34="",P34=0),"",S34/P34) | U34: =IF(S34="","",S34*Punktwert*Kontrakte-Kommission*Kontrakte) | V34: =IF(U34="","",SUM($U$5:U34)) | W34: =IF(V34="","",MAX(0,MAX($V$5:V34))) | X34: =IF(V34="","",V34-W34) | Y34: =IF(N34<>"Trade","",IF(P34=0,"Stop = Einstieg?",IF(I34="","Ergebnis eintragen",IF(AND(I34="Zeit",J34=""),"Kurs 11:30 fehlt",IF(OR(AND(M34="Short",H34>F34),AND(M34="Long",H34<G34)),"Einstieg prüfen","ok"))))) | Z34: =IF(A34="","",WEEKDAY(A34,2))
L35: =IF(OR(B35="",C35=""),"",(C35-B35)/B35) | M35: =IF(L35="","",IF(ABS(L35)<MinDrive,"kein Trade",IF(L35>0,"Short","Long"))) | N35: =IF(OR(M35="",M35="kein Trade"),"",IF(H35="","kein Signal","Trade")) | O35: =IF(N35<>"Trade","",IF(M35="Short",D35,E35)) | P35: =IF(N35<>"Trade","",ABS(H35-O35)) | Q35: =IF(N35<>"Trade","",H35+IF(M35="Long",1,-1)*ZielR*P35) | R35: =IF(OR(N35<>"Trade",I35=""),"",IF(I35="Ziel",Q35,IF(I35="Stop",O35,IF(J35="","",J35)))) | S35: =IF(R35="","",(R35-H35)*IF(M35="Long",1,-1)-2*Slippage) | T35: =IF(OR(S35="",P35=0),"",S35/P35) | U35: =IF(S35="","",S35*Punktwert*Kontrakte-Kommission*Kontrakte) | V35: =IF(U35="","",SUM($U$5:U35)) | W35: =IF(V35="","",MAX(0,MAX($V$5:V35))) | X35: =IF(V35="","",V35-W35) | Y35: =IF(N35<>"Trade","",IF(P35=0,"Stop = Einstieg?",IF(I35="","Ergebnis eintragen",IF(AND(I35="Zeit",J35=""),"Kurs 11:30 fehlt",IF(OR(AND(M35="Short",H35>F35),AND(M35="Long",H35<G35)),"Einstieg prüfen","ok"))))) | Z35: =IF(A35="","",WEEKDAY(A35,2))
L36: =IF(OR(B36="",C36=""),"",(C36-B36)/B36) | M36: =IF(L36="","",IF(ABS(L36)<MinDrive,"kein Trade",IF(L36>0,"Short","Long"))) | N36: =IF(OR(M36="",M36="kein Trade"),"",IF(H36="","kein Signal","Trade")) | O36: =IF(N36<>"Trade","",IF(M36="Short",D36,E36)) | P36: =IF(N36<>"Trade","",ABS(H36-O36)) | Q36: =IF(N36<>"Trade","",H36+IF(M36="Long",1,-1)*ZielR*P36) | R36: =IF(OR(N36<>"Trade",I36=""),"",IF(I36="Ziel",Q36,IF(I36="Stop",O36,IF(J36="","",J36)))) | S36: =IF(R36="","",(R36-H36)*IF(M36="Long",1,-1)-2*Slippage) | T36: =IF(OR(S36="",P36=0),"",S36/P36) | U36: =IF(S36="","",S36*Punktwert*Kontrakte-Kommission*Kontrakte) | V36: =IF(U36="","",SUM($U$5:U36)) | W36: =IF(V36="","",MAX(0,MAX($V$5:V36))) | X36: =IF(V36="","",V36-W36) | Y36: =IF(N36<>"Trade","",IF(P36=0,"Stop = Einstieg?",IF(I36="","Ergebnis eintragen",IF(AND(I36="Zeit",J36=""),"Kurs 11:30 fehlt",IF(OR(AND(M36="Short",H36>F36),AND(M36="Long",H36<G36)),"Einstieg prüfen","ok"))))) | Z36: =IF(A36="","",WEEKDAY(A36,2))
L37: =IF(OR(B37="",C37=""),"",(C37-B37)/B37) | M37: =IF(L37="","",IF(ABS(L37)<MinDrive,"kein Trade",IF(L37>0,"Short","Long"))) | N37: =IF(OR(M37="",M37="kein Trade"),"",IF(H37="","kein Signal","Trade")) | O37: =IF(N37<>"Trade","",IF(M37="Short",D37,E37)) | P37: =IF(N37<>"Trade","",ABS(H37-O37)) | Q37: =IF(N37<>"Trade","",H37+IF(M37="Long",1,-1)*ZielR*P37) | R37: =IF(OR(N37<>"Trade",I37=""),"",IF(I37="Ziel",Q37,IF(I37="Stop",O37,IF(J37="","",J37)))) | S37: =IF(R37="","",(R37-H37)*IF(M37="Long",1,-1)-2*Slippage) | T37: =IF(OR(S37="",P37=0),"",S37/P37) | U37: =IF(S37="","",S37*Punktwert*Kontrakte-Kommission*Kontrakte) | V37: =IF(U37="","",SUM($U$5:U37)) | W37: =IF(V37="","",MAX(0,MAX($V$5:V37))) | X37: =IF(V37="","",V37-W37) | Y37: =IF(N37<>"Trade","",IF(P37=0,"Stop = Einstieg?",IF(I37="","Ergebnis eintragen",IF(AND(I37="Zeit",J37=""),"Kurs 11:30 fehlt",IF(OR(AND(M37="Short",H37>F37),AND(M37="Long",H37<G37)),"Einstieg prüfen","ok"))))) | Z37: =IF(A37="","",WEEKDAY(A37,2))
L38: =IF(OR(B38="",C38=""),"",(C38-B38)/B38) | M38: =IF(L38="","",IF(ABS(L38)<MinDrive,"kein Trade",IF(L38>0,"Short","Long"))) | N38: =IF(OR(M38="",M38="kein Trade"),"",IF(H38="","kein Signal","Trade")) | O38: =IF(N38<>"Trade","",IF(M38="Short",D38,E38)) | P38: =IF(N38<>"Trade","",ABS(H38-O38)) | Q38: =IF(N38<>"Trade","",H38+IF(M38="Long",1,-1)*ZielR*P38) | R38: =IF(OR(N38<>"Trade",I38=""),"",IF(I38="Ziel",Q38,IF(I38="Stop",O38,IF(J38="","",J38)))) | S38: =IF(R38="","",(R38-H38)*IF(M38="Long",1,-1)-2*Slippage) | T38: =IF(OR(S38="",P38=0),"",S38/P38) | U38: =IF(S38="","",S38*Punktwert*Kontrakte-Kommission*Kontrakte) | V38: =IF(U38="","",SUM($U$5:U38)) | W38: =IF(V38="","",MAX(0,MAX($V$5:V38))) | X38: =IF(V38="","",V38-W38) | Y38: =IF(N38<>"Trade","",IF(P38=0,"Stop = Einstieg?",IF(I38="","Ergebnis eintragen",IF(AND(I38="Zeit",J38=""),"Kurs 11:30 fehlt",IF(OR(AND(M38="Short",H38>F38),AND(M38="Long",H38<G38)),"Einstieg prüfen","ok"))))) | Z38: =IF(A38="","",WEEKDAY(A38,2))
... L204: =IF(OR(B204="",C204=""),"",(C204-B204)/B204) | M204: =IF(L204="","",IF(ABS(L204)<MinDrive,"kein Trade",IF(L204>0,"Short","Long"))) | N204: =IF(OR(M204="",M204="kein Trade"),"",IF(H204="","kein Signal","Trade")) | O204: =IF(N204<>"Trade","",IF(M204="Short",D204,E204)) | P204: =IF(N204<>"Trade","",ABS(H204-O204)) | Q204: =IF(N204<>"Trade","",H204+IF(M204="Long",1,-1)*ZielR*P204) | R204: =IF(OR(N204<>"Trade",I204=""),"",IF(I204="Ziel",Q204,IF(I204="Stop",O204,IF(J204="","",J204)))) | S204: =IF(R204="","",(R204-H204)*IF(M204="Long",1,-1)-2*Slippage) | T204: =IF(OR(S204="",P204=0),"",S204/P204) | U204: =IF(S204="","",S204*Punktwert*Kontrakte-Kommission*Kontrakte) | V204: =IF(U204="","",SUM($U$5:U204)) | W204: =IF(V204="","",MAX(0,MAX($V$5:V204))) | X204: =IF(V204="","",V204-W204) | Y204: =IF(N204<>"Trade","",IF(P204=0,"Stop = Einstieg?",IF(I204="","Ergebnis eintragen",IF(AND(I204="Zeit",J204=""),"Kurs 11:30 fehlt",IF(OR(AND(M204="Short",H204>F204),AND(M204="Long",H204<G204)),"Einstieg prüfen","ok"))))) | Z204: =IF(A204="","",WEEKDAY(A204,2))

Sheet Übersicht
A1: Übersicht
A2: Alles automatisch aus dem Journal berechnet.
A4: Zeitraum von | B4: =IF(COUNT(Journal!$A$5:$A$204)=0,"",MIN(Journal!$A$5:$A$204)) -> 46287
A5: Zeitraum bis | B5: =IF(COUNT(Journal!$A$5:$A$204)=0,"",MAX(Journal!$A$5:$A$204)) -> 46316
A6: Erfasste Tage | B6: =COUNT(Journal!$L$5:$L$204) -> 0
A7: Tage mit Trade | B7: =COUNTIF(Journal!$N$5:$N$204,"Trade") -> 0
A8: davon abgeschlossen | B8: =COUNT(Journal!$U$5:$U$204) -> 0
A9: Gewinner | B9: =COUNTIF(Journal!$U$5:$U$204,">0") -> 0
A10: Verlierer | B10: =COUNTIF(Journal!$U$5:$U$204,"<=0") -> 0
A11: Trefferquote | B11: =IF(B8=0,"",B9/B8)
A12: Gewinn/Verlust gesamt | B12: =SUM(Journal!$U$5:$U$204) -> 0
A13: Ø pro Trade | B13: =IF(B8=0,"",AVERAGE(Journal!$U$5:$U$204))
A14: Ø R pro Trade | B14: =IF(COUNT(Journal!$T$5:$T$204)=0,"",AVERAGE(Journal!$T$5:$T$204))
A15: Profit Factor | B15: =IF(SUMIF(Journal!$U$5:$U$204,"<0")=0,"",SUMIF(Journal!$U$5:$U$204,">0")/-SUMIF(Journal!$U$5:$U$204,"<0"))
A16: Größter Gewinn | B16: =IF(B8=0,"",MAX(Journal!$U$5:$U$204))
A17: Größter Verlust | B17: =IF(B8=0,"",MIN(Journal!$U$5:$U$204))
A18: Max. Drawdown | B18: =MIN(Journal!$X$5:$X$204) -> 0
A19: Exit am Ziel | B19: =COUNTIFS(Journal!$N$5:$N$204,"Trade",Journal!$I$5:$I$204,"Ziel") -> 0
A20: Exit am Stop | B20: =COUNTIFS(Journal!$N$5:$N$204,"Trade",Journal!$I$5:$I$204,"Stop") -> 0
A21: Exit um 11:30 | B21: =COUNTIFS(Journal!$N$5:$N$204,"Trade",Journal!$I$5:$I$204,"Zeit") -> 0
A24: Nach Monat
A25: Monat | B25: Trades | C25: Gewinner | D25: Trefferquote | E25: Gewinn/Verlust | F25: Ø R
A26: =IF(COUNT(Journal!$A$5:$A$204)=0,"",DATE(YEAR(MIN(Journal!$A$5:$A$204)),MONTH(MIN(Journal!$A$5:$A$204)),1)) -> 46266 | B26: =IF($A26="","",COUNTIFS(Journal!$U$5:$U$204,">-1E+99",Journal!$A$5:$A$204,">="&$A26,Journal!$A$5:$A$204,"<"&EDATE($A26,1))) -> 0 | C26: =IF($A26="","",COUNTIFS(Journal!$U$5:$U$204,">0",Journal!$A$5:$A$204,">="&$A26,Journal!$A$5:$A$204,"<"&EDATE($A26,1))) -> 0 | D26: =IF(OR($A26="",N(B26)=0),"",C26/B26) | E26: =IF($A26="","",SUMIFS(Journal!$U$5:$U$204,Journal!$A$5:$A$204,">="&$A26,Journal!$A$5:$A$204,"<"&EDATE($A26,1))) -> 0 | F26: =IF(OR($A26="",N(B26)=0),"",SUMIFS(Journal!$T$5:$T$204,Journal!$A$5:$A$204,">="&$A26,Journal!$A$5:$A$204,"<"&EDATE($A26,1))/B26)
A27: =IF(A26="","",IF(EDATE(A26,1)>MAX(Journal!$A$5:$A$204),"",EDATE(A26,1))) -> 46296 | B27: =IF($A27="","",COUNTIFS(Journal!$U$5:$U$204,">-1E+99",Journal!$A$5:$A$204,">="&$A27,Journal!$A$5:$A$204,"<"&EDATE($A27,1))) -> 0 | C27: =IF($A27="","",COUNTIFS(Journal!$U$5:$U$204,">0",Journal!$A$5:$A$204,">="&$A27,Journal!$A$5:$A$204,"<"&EDATE($A27,1))) -> 0 | D27: =IF(OR($A27="",N(B27)=0),"",C27/B27) | E27: =IF($A27="","",SUMIFS(Journal!$U$5:$U$204,Journal!$A$5:$A$204,">="&$A27,Journal!$A$5:$A$204,"<"&EDATE($A27,1))) -> 0 | F27: =IF(OR($A27="",N(B27)=0),"",SUMIFS(Journal!$T$5:$T$204,Journal!$A$5:$A$204,">="&$A27,Journal!$A$5:$A$204,"<"&EDATE($A27,1))/B27)
A28: =IF(A27="","",IF(EDATE(A27,1)>MAX(Journal!$A$5:$A$204),"",EDATE(A27,1))) | B28: =IF($A28="","",COUNTIFS(Journal!$U$5:$U$204,">-1E+99",Journal!$A$5:$A$204,">="&$A28,Journal!$A$5:$A$204,"<"&EDATE($A28,1))) | C28: =IF($A28="","",COUNTIFS(Journal!$U$5:$U$204,">0",Journal!$A$5:$A$204,">="&$A28,Journal!$A$5:$A$204,"<"&EDATE($A28,1))) | D28: =IF(OR($A28="",N(B28)=0),"",C28/B28) | E28: =IF($A28="","",SUMIFS(Journal!$U$5:$U$204,Journal!$A$5:$A$204,">="&$A28,Journal!$A$5:$A$204,"<"&EDATE($A28,1))) | F28: =IF(OR($A28="",N(B28)=0),"",SUMIFS(Journal!$T$5:$T$204,Journal!$A$5:$A$204,">="&$A28,Journal!$A$5:$A$204,"<"&EDATE($A28,1))/B28)
A29: =IF(A28="","",IF(EDATE(A28,1)>MAX(Journal!$A$5:$A$204),"",EDATE(A28,1))) | B29: =IF($A29="","",COUNTIFS(Journal!$U$5:$U$204,">-1E+99",Journal!$A$5:$A$204,">="&$A29,Journal!$A$5:$A$204,"<"&EDATE($A29,1))) | C29: =IF($A29="","",COUNTIFS(Journal!$U$5:$U$204,">0",Journal!$A$5:$A$204,">="&$A29,Journal!$A$5:$A$204,"<"&EDATE($A29,1))) | D29: =IF(OR($A29="",N(B29)=0),"",C29/B29) | E29: =IF($A29="","",SUMIFS(Journal!$U$5:$U$204,Journal!$A$5:$A$204,">="&$A29,Journal!$A$5:$A$204,"<"&EDATE($A29,1))) | F29: =IF(OR($A29="",N(B29)=0),"",SUMIFS(Journal!$T$5:$T$204,Journal!$A$5:$A$204,">="&$A29,Journal!$A$5:$A$204,"<"&EDATE($A29,1))/B29)
A30: =IF(A29="","",IF(EDATE(A29,1)>MAX(Journal!$A$5:$A$204),"",EDATE(A29,1))) | B30: =IF($A30="","",COUNTIFS(Journal!$U$5:$U$204,">-1E+99",Journal!$A$5:$A$204,">="&$A30,Journal!$A$5:$A$204,"<"&EDATE($A30,1))) | C30: =IF($A30="","",COUNTIFS(Journal!$U$5:$U$204,">0",Journal!$A$5:$A$204,">="&$A30,Journal!$A$5:$A$204,"<"&EDATE($A30,1))) | D30: =IF(OR($A30="",N(B30)=0),"",C30/B30) | E30: =IF($A30="","",SUMIFS(Journal!$U$5:$U$204,Journal!$A$5:$A$204,">="&$A30,Journal!$A$5:$A$204,"<"&EDATE($A30,1))) | F30: =IF(OR($A30="",N(B30)=0),"",SUMIFS(Journal!$T$5:$T$204,Journal!$A$5:$A$204,">="&$A30,Journal!$A$5:$A$204,"<"&EDATE($A30,1))/B30)
A31: =IF(A30="","",IF(EDATE(A30,1)>MAX(Journal!$A$5:$A$204),"",EDATE(A30,1))) | B31: =IF($A31="","",COUNTIFS(Journal!$U$5:$U$204,">-1E+99",Journal!$A$5:$A$204,">="&$A31,Journal!$A$5:$A$204,"<"&EDATE($A31,1))) | C31: =IF($A31="","",COUNTIFS(Journal!$U$5:$U$204,">0",Journal!$A$5:$A$204,">="&$A31,Journal!$A$5:$A$204,"<"&EDATE($A31,1))) | D31: =IF(OR($A31="",N(B31)=0),"",C31/B31) | E31: =IF($A31="","",SUMIFS(Journal!$U$5:$U$204,Journal!$A$5:$A$204,">="&$A31,Journal!$A$5:$A$204,"<"&EDATE($A31,1))) | F31: =IF(OR($A31="",N(B31)=0),"",SUMIFS(Journal!$T$5:$T$204,Journal!$A$5:$A$204,">="&$A31,Journal!$A$5:$A$204,"<"&EDATE($A31,1))/B31)
A32: =IF(A31="","",IF(EDATE(A31,1)>MAX(Journal!$A$5:$A$204),"",EDATE(A31,1))) | B32: =IF($A32="","",COUNTIFS(Journal!$U$5:$U$204,">-1E+99",Journal!$A$5:$A$204,">="&$A32,Journal!$A$5:$A$204,"<"&EDATE($A32,1))) | C32: =IF($A32="","",COUNTIFS(Journal!$U$5:$U$204,">0",Journal!$A$5:$A$204,">="&$A32,Journal!$A$5:$A$204,"<"&EDATE($A32,1))) | D32: =IF(OR($A32="",N(B32)=0),"",C32/B32) | E32: =IF($A32="","",SUMIFS(Journal!$U$5:$U$204,Journal!$A$5:$A$204,">="&$A32,Journal!$A$5:$A$204,"<"&EDATE($A32,1))) | F32: =IF(OR($A32="",N(B32)=0),"",SUMIFS(Journal!$T$5:$T$204,Journal!$A$5:$A$204,">="&$A32,Journal!$A$5:$A$204,"<"&EDATE($A32,1))/B32)
A33: =IF(A32="","",IF(EDATE(A32,1)>MAX(Journal!$A$5:$A$204),"",EDATE(A32,1))) | B33: =IF($A33="","",COUNTIFS(Journal!$U$5:$U$204,">-1E+99",Journal!$A$5:$A$204,">="&$A33,Journal!$A$5:$A$204,"<"&EDATE($A33,1))) | C33: =IF($A33="","",COUNTIFS(Journal!$U$5:$U$204,">0",Journal!$A$5:$A$204,">="&$A33,Journal!$A$5:$A$204,"<"&EDATE($A33,1))) | D33: =IF(OR($A33="",N(B33)=0),"",C33/B33) | E33: =IF($A33="","",SUMIFS(Journal!$U$5:$U$204,Journal!$A$5:$A$204,">="&$A33,Journal!$A$5:$A$204,"<"&EDATE($A33,1))) | F33: =IF(OR($A33="",N(B33)=0),"",SUMIFS(Journal!$T$5:$T$204,Journal!$A$5:$A$204,">="&$A33,Journal!$A$5:$A$204,"<"&EDATE($A33,1))/B33)
A34: =IF(A33="","",IF(EDATE(A33,1)>MAX(Journal!$A$5:$A$204),"",EDATE(A33,1))) | B34: =IF($A34="","",COUNTIFS(Journal!$U$5:$U$204,">-1E+99",Journal!$A$5:$A$204,">="&$A34,Journal!$A$5:$A$204,"<"&EDATE($A34,1))) | C34: =IF($A34="","",COUNTIFS(Journal!$U$5:$U$204,">0",Journal!$A$5:$A$204,">="&$A34,Journal!$A$5:$A$204,"<"&EDATE($A34,1))) | D34: =IF(OR($A34="",N(B34)=0),"",C34/B34) | E34: =IF($A34="","",SUMIFS(Journal!$U$5:$U$204,Journal!$A$5:$A$204,">="&$A34,Journal!$A$5:$A$204,"<"&EDATE($A34,1))) | F34: =IF(OR($A34="",N(B34)=0),"",SUMIFS(Journal!$T$5:$T$204,Journal!$A$5:$A$204,">="&$A34,Journal!$A$5:$A$204,"<"&EDATE($A34,1))/B34)
A35: =IF(A34="","",IF(EDATE(A34,1)>MAX(Journal!$A$5:$A$204),"",EDATE(A34,1))) | B35: =IF($A35="","",COUNTIFS(Journal!$U$5:$U$204,">-1E+99",Journal!$A$5:$A$204,">="&$A35,Journal!$A$5:$A$204,"<"&EDATE($A35,1))) | C35: =IF($A35="","",COUNTIFS(Journal!$U$5:$U$204,">0",Journal!$A$5:$A$204,">="&$A35,Journal!$A$5:$A$204,"<"&EDATE($A35,1))) | D35: =IF(OR($A35="",N(B35)=0),"",C35/B35) | E35: =IF($A35="","",SUMIFS(Journal!$U$5:$U$204,Journal!$A$5:$A$204,">="&$A35,Journal!$A$5:$A$204,"<"&EDATE($A35,1))) | F35: =IF(OR($A35="",N(B35)=0),"",SUMIFS(Journal!$T$5:$T$204,Journal!$A$5:$A$204,">="&$A35,Journal!$A$5:$A$204,"<"&EDATE($A35,1))/B35)
A36: =IF(A35="","",IF(EDATE(A35,1)>MAX(Journal!$A$5:$A$204),"",EDATE(A35,1))) | B36: =IF($A36="","",COUNTIFS(Journal!$U$5:$U$204,">-1E+99",Journal!$A$5:$A$204,">="&$A36,Journal!$A$5:$A$204,"<"&EDATE($A36,1))) | C36: =IF($A36="","",COUNTIFS(Journal!$U$5:$U$204,">0",Journal!$A$5:$A$204,">="&$A36,Journal!$A$5:$A$204,"<"&EDATE($A36,1))) | D36: =IF(OR($A36="",N(B36)=0),"",C36/B36) | E36: =IF($A36="","",SUMIFS(Journal!$U$5:$U$204,Journal!$A$5:$A$204,">="&$A36,Journal!$A$5:$A$204,"<"&EDATE($A36,1))) | F36: =IF(OR($A36="",N(B36)=0),"",SUMIFS(Journal!$T$5:$T$204,Journal!$A$5:$A$204,">="&$A36,Journal!$A$5:$A$204,"<"&EDATE($A36,1))/B36)
A37: =IF(A36="","",IF(EDATE(A36,1)>MAX(Journal!$A$5:$A$204),"",EDATE(A36,1))) | B37: =IF($A37="","",COUNTIFS(Journal!$U$5:$U$204,">-1E+99",Journal!$A$5:$A$204,">="&$A37,Journal!$A$5:$A$204,"<"&EDATE($A37,1))) | C37: =IF($A37="","",COUNTIFS(Journal!$U$5:$U$204,">0",Journal!$A$5:$A$204,">="&$A37,Journal!$A$5:$A$204,"<"&EDATE($A37,1))) | D37: =IF(OR($A37="",N(B37)=0),"",C37/B37) | E37: =IF($A37="","",SUMIFS(Journal!$U$5:$U$204,Journal!$A$5:$A$204,">="&$A37,Journal!$A$5:$A$204,"<"&EDATE($A37,1))) | F37: =IF(OR($A37="",N(B37)=0),"",SUMIFS(Journal!$T$5:$T$204,Journal!$A$5:$A$204,">="&$A37,Journal!$A$5:$A$204,"<"&EDATE($A37,1))/B37)
A39: Nach Wochentag
A40: Wochentag | B40: Trades | C40: Gewinner | D40: Trefferquote | E40: Gewinn/Verlust | F40: Ø R
A41: Montag | B41: =(COUNTIFS(Journal!$U$5:$U$204,">-1E+99",Journal!$Z$5:$Z$204,1)) -> 0 | C41: =(COUNTIFS(Journal!$U$5:$U$204,">0",Journal!$Z$5:$Z$204,1)) -> 0 | D41: =IF(OR($A41="",N(B41)=0),"",C41/B41) | E41: =(SUMIFS(Journal!$U$5:$U$204,Journal!$Z$5:$Z$204,1)) -> 0 | F41: =IF(OR($A41="",N(B41)=0),"",SUMIFS(Journal!$T$5:$T$204,Journal!$Z$5:$Z$204,1)/B41)
A42: Dienstag | B42: =(COUNTIFS(Journal!$U$5:$U$204,">-1E+99",Journal!$Z$5:$Z$204,2)) -> 0 | C42: =(COUNTIFS(Journal!$U$5:$U$204,">0",Journal!$Z$5:$Z$204,2)) -> 0 | D42: =IF(OR($A42="",N(B42)=0),"",C42/B42) | E42: =(SUMIFS(Journal!$U$5:$U$204,Journal!$Z$5:$Z$204,2)) -> 0 | F42: =IF(OR($A42="",N(B42)=0),"",SUMIFS(Journal!$T$5:$T$204,Journal!$Z$5:$Z$204,2)/B42)
A43: Mittwoch | B43: =(COUNTIFS(Journal!$U$5:$U$204,">-1E+99",Journal!$Z$5:$Z$204,3)) -> 0 | C43: =(COUNTIFS(Journal!$U$5:$U$204,">0",Journal!$Z$5:$Z$204,3)) -> 0 | D43: =IF(OR($A43="",N(B43)=0),"",C43/B43) | E43: =(SUMIFS(Journal!$U$5:$U$204,Journal!$Z$5:$Z$204,3)) -> 0 | F43: =IF(OR($A43="",N(B43)=0),"",SUMIFS(Journal!$T$5:$T$204,Journal!$Z$5:$Z$204,3)/B43)
A44: Donnerstag | B44: =(COUNTIFS(Journal!$U$5:$U$204,">-1E+99",Journal!$Z$5:$Z$204,4)) -> 0 | C44: =(COUNTIFS(Journal!$U$5:$U$204,">0",Journal!$Z$5:$Z$204,4)) -> 0 | D44: =IF(OR($A44="",N(B44)=0),"",C44/B44) | E44: =(SUMIFS(Journal!$U$5:$U$204,Journal!$Z$5:$Z$204,4)) -> 0 | F44: =IF(OR($A44="",N(B44)=0),"",SUMIFS(Journal!$T$5:$T$204,Journal!$Z$5:$Z$204,4)/B44)
...

Sheet Einstellungen
A1: Einstellungen
A2: Gelbe Zellen mit blauer Schrift dürfen geändert werden.
A4: Mindestbewegung 09:30–10:00 | B4: 0.002 | C4: Kleinere Bewegungen werden nicht gehandelt.
A5: Ziel in R (Vielfaches des Risikos) | B5: 2 | C5: 2 = Ziel liegt doppelt so weit weg wie der Stop.
A6: $ pro Punkt und Kontrakt | B6: 20 | C6: NQ = 20, MNQ = 2, QQQ-Aktie = 1 (dann Kontrakte = Stückzahl).
A7: Kontrakte / Stück | B7: 1
A8: Gebühr pro Kontrakt (Hin + Rück) in $ | B8: 4 | C8: Je nach Broker; MNQ etwa 1,50 $.
A9: Slippage pro Seite in Punkten | B9: 0.25 | C9: 1 Tick NQ = 0,25 Punkte; wird bei Ein- und Ausstieg abgezogen.
A11: Standardwerte entsprechen dem Python-Backtest (backtest/strategy.py): 0,2 % Mindestbewegung, 2R-Ziel, Exit 11:30.
