Workbook

Sheet Rechner
B1: Hauskauf-Rechner Damme – Verkauf mit Rückmietung
B2: Nur die gelben Felder mit blauer Schrift ändern. Alle anderen Werte werden berechnet. Vorbelegt: Beispielhaus Damme (keine echten Objektdaten).
B5: Objekt | G5: Ergebnis
B6: Kaufpreis | C6: 260000 | D6: € | E6: Verhandelter Kaufpreis | G6: Kaltmiete Verkäufer / Monat | H6: =$C$7*$C$8
B7: Wohnfläche Verkäufer | C7: 125 | D7: m² | E7: Fläche der Wohnung, in der der Verkäufer bleibt | G7: Kaltmiete gesamt / Monat | H7: =$H$6+$C$11
B8: Kaltmiete Verkäufer | C8: 7.5 | D8: €/m² | E8: Damme 2026: ca. 7,15–9,90 €/m² (Mietspiegel-Portale) | G8: Kaufnebenkosten | H8: =$C$6*($C$13+$C$14+$C$15)
B9: Sofort-Investitionen | C9: 0 | D9: € | E9: z. B. Heizung, GEG-Pflichten nach Eigentümerwechsel | G9: Gesamtinvestition | H9: =$C$6+$H$8+$C$9
B10: Einliegerwohnung Fläche | C10: 0 | D10: m² | E10: 0, wenn keine vorhanden | G10: Darlehen | H10: =MAX(0,$H$9-$C$17)
B11: Einliegerwohnung Miete | C11: 0 | D11: €/Monat | E11: Kaltmiete der zweiten Einheit | G11: Monatliche Rechnung (Durchschnitt 1. Jahr)
B12: Kaufnebenkosten | G12: Kaltmiete | H12: =$H$7
B13: Grunderwerbsteuer | C13: 0.05 | D13: % | E13: Niedersachsen: 5 % | G13: Mietausfall-Reserve | H13: =-$H$7*$C$25
B14: Notar & Grundbuch | C14: 0.02 | D14: % | E14: üblich ca. 1,5–2 % | G14: Kreditrate (Zins + Tilgung) | H14: =-$H$10*($C$18+$C$19)/12
B15: Makler | C15: 0 | D15: % | E15: bei Direktkauf 0 % | G15: Instandhaltungsrücklage | H15: =-($C$7+$C$10)*$C$23/12
B16: Finanzierung | G16: Nicht umlagefähige Kosten | H16: =-$C$24
B17: Eigenkapital | C17: 55000 | D17: € | E17: eingesetztes Eigenkapital | G17: Cashflow vor Steuern | H17: =SUM($H$12:$H$16)
B18: Sollzins | C18: 0.038 | D18: % p. a. | E18: Annahme – aktuelles Bankangebot eintragen | G18: Steuereffekt (+ = Ersparnis) | H18: =-$H$30/12
B19: Anfängliche Tilgung | C19: 0.02 | D19: % p. a. | E19: Rate = Darlehen × (Zins + Tilgung) ÷ 12 | G19: CASHFLOW NACH STEUERN / MONAT | H19: =$H$17+$H$18 | I19: =IF($H$19>=0,"Trägt sich selbst",IF($H$19>=-150,"Leichter Zuschuss nötig","Deutlicher Zuschuss nötig"))
B20: Zinsbindung | C20: 10 | D20: Jahre | E20: danach gilt der Anschlusszins (Rate bleibt gleich) | G20: Kennzahlen
B21: Anschlusszins | C21: 0.045 | D21: % p. a. | E21: Annahme für die Zeit nach der Zinsbindung | G21: Kaufpreisfaktor | H21: =IFERROR($C$6/($H$7*12),0) | I21: =IF($H$21<=18,"günstig",IF($H$21<=22,"mittel","teuer"))
B22: Laufende Kosten & Steuer | G22: Bruttomietrendite | H22: =IFERROR($H$7*12/$C$6,0)
B23: Instandhaltung | C23: 14 | D23: €/m² · Jahr | E23: Altbau: ca. 12–18 € | G23: Nettomietrendite | H23: =IFERROR(($H$12+$H$13+$H$15+$H$16)*12/$H$9,0)
B24: Nicht umlagefähige Kosten | C24: 20 | D24: €/Monat | E24: Verwaltung, Bankgebühren | G24: Eigenkapitalrendite (CF + Tilgung) | H24: =IFERROR(($H$19*12+$H$27)/$C$17,0)
B25: Mietausfall-Reserve | C25: 0.02 | D25: % der Miete | G25: Steuer 1. Jahr (vereinfacht)
B26: Gebäudeanteil | C26: 0.7 | D26: % vom Kaufpreis | E26: Rest = Grundstück (nicht abschreibbar) | G26: Zinsen Jahr 1 (monatsgenau) | H26: =-Prognose!$G$5
B27: AfA-Satz | C27: 0.02 | D27: % p. a. | E27: Baujahr 1925–2022: 2 %, vor 1925: 2,5 % | G27: Tilgung Jahr 1 (Vermögensaufbau) | H27: =-Prognose!$H$5
B28: Persönlicher Steuersatz | C28: 0.3 | D28: % | E28: Grenzsteuersatz | G28: AfA pro Jahr | H28: =(($C$6+$H$8)*$C$26+$C$9)*$C$27
B29: Entwicklung (für Blatt Prognose) | G29: Steuerliches Ergebnis | H29: =($H$12+$H$13+$H$15+$H$16)*12-$H$26-$H$28
B30: Mietsteigerung | C30: 0.015 | D30: % p. a. | E30: Annahme; gesetzlich begrenzt (Mietspiegel, Kappungsgrenze) | G30: Steuer (+ zahlen / − Erstattung) | H30: =$H$29*$C$28
B31: Kostensteigerung | C31: 0.02 | D31: % p. a. | E31: Annahme für Instandhaltung und sonstige Kosten | G31: Maximaler Kaufpreis
B32: Wertsteigerung | C32: 0.015 | D32: % p. a. | E32: Annahme | G32: Max. Kaufpreis für Cashflow ≥ 0 | H32: =IF($H$10<=0,"–",MAX(0,$C$6+$H$19/((1+$C$13+$C$14+$C$15)/12*(($C$18+$C$19)-$C$28*($H$26/$H$10+$C$26*$C$27)))))
B33: Verkäufer | G33: Nötiger Abschlag | H33: =IF(ISNUMBER($H$32),MAX(0,$C$6-$H$32),0)
B34: Alter (jüngste Person) | C34: 75 | D34: Jahre | E34: Tabelle reicht von 60 bis 95 Jahre | G34: Nötiger Abschlag in % | H34: =IFERROR($H$33/$C$6,0) | I34: =IF($H$10<=0,"kein Darlehen – Formel nicht nötig",IF($H$33=0,"Preis passt","so viel Abschlag bräuchtest du"))
B35: Zins auf sein Kapital | C35: 0.025 | D35: % p. a. | E35: Tagesgeld/Anleihen, Annahme | G35: Sicht des Verkäufers
G36: Erlös für den Verkäufer | H36: =$C$6
G37: Seine Miete pro Jahr | H37: =$H$6*12
G38: Lebenserwartung (Jahre, ca.) | H38: =INDEX(Lebenserwartung!$B$4:$B$11,MATCH(MIN(MAX($C$34,60),94.99),Lebenserwartung!$A$4:$A$11,1))+(INDEX(Lebenserwartung!$B$4:$B$11,MATCH(MIN(MAX($C$34,60),94.99),Lebenserwartung!$A$4:$A$11,1)+1)-INDEX(Lebenserwartung!$B$4:$B$11,MATCH(MIN(MAX($C$34,60),94.99),Lebenserwartung!$A$4:$A$11,1)))*(MIN(MAX($C$34,60),95)-INDEX(Lebenserwartung!$A$4:$A$11,MATCH(MIN(MAX($C$34,60),94.99),Lebenserwartung!$A$4:$A$11,1)))/(INDEX(Lebenserwartung!$A$4:$A$11,MATCH(MIN(MAX($C$34,60),94.99),Lebenserwartung!$A$4:$A$11,1)+1)-INDEX(Lebenserwartung!$A$4:$A$11,MATCH(MIN(MAX($C$34,60),94.99),Lebenserwartung!$A$4:$A$11,1)))
G39: So lange reicht das Geld (Jahre) | H39: =IF($H$37<=0,"unbegrenzt",IF($C$35=0,$C$6/$H$37,IF($H$37<=$C$6*$C$35,"unbegrenzt",NPER($C$35,-$H$37,$C$6))))
G40: Rest nach Lebenserwartung | H40: =MAX(0,IF($C$35=0,$C$6-$H$37*$H$38,FV($C$35,$H$38,$H$37,-$C$6)))
G41: Bewertung | H41: =IF($H$39="unbegrenzt","Geld reicht sicher",IF($H$39>$H$38,"Geld reicht sicher","Achtung: Geld reicht voraussichtlich nicht"))
G43: Kontrolle
...

Sheet Prognose
A1: Prognose über 30 Jahre (Werte pro Jahr)
A2: Basiert auf dem Blatt Rechner. Zinsen/Tilgung monatsgenau; Miete und Kosten steigen mit den eingegebenen Raten. Grüne Schrift = Bezug auf das Blatt Rechner.
A4: Jahr | B4: Zinssatz | C4: Restschuld Anfang | D4: Kaltmiete | E4: Mietausfall | F4: Instandh. + Kosten | G4: Zinsen | H4: Tilgung | I4: Restschuld Ende | J4: Cashflow vor Steuern | K4: AfA | L4: Steuereffekt | M4: Cashflow nach Steuern | N4: Kumulierter Cashflow | O4: Immobilienwert | P4: Eigenkapital im Objekt
A5: 1 | B5: =IF(A5<=Rechner!$C$20,Rechner!$C$18,Rechner!$C$21) | C5: =Rechner!$H$10 | D5: =Rechner!$H$7*12*(1+Rechner!$C$30)^(A5-1) | E5: =-D5*Rechner!$C$25 | F5: =(Rechner!$H$15+Rechner!$H$16)*12*(1+Rechner!$C$31)^(A5-1) | G5: =IF(C5<=0,0,IF(I5>0,-(12*(Rechner!$H$10*(Rechner!$C$18+Rechner!$C$19)/12)-(C5-I5)),IF(B5=0,0,-((Rechner!$H$10*(Rechner!$C$18+Rechner!$C$19)/12)*NPER(B5/12,-(Rechner!$H$10*(Rechner!$C$18+Rechner!$C$19)/12),C5)-C5)))) | H5: =-(C5-I5) | I5: =IF(C5<=0,0,IF(B5=0,MAX(0,C5-12*(Rechner!$H$10*(Rechner!$C$18+Rechner!$C$19)/12)),MAX(0,(C5*(1+B5/12)^12-(Rechner!$H$10*(Rechner!$C$18+Rechner!$C$19)/12)*((1+B5/12)^12-1)/(B5/12))))) | J5: =D5+E5+F5+G5+H5 | K5: =-Rechner!$H$28*(A5<=1/Rechner!$C$27) | L5: =-(D5+E5+F5+G5+K5)*Rechner!$C$28 | M5: =J5+L5 | N5: =M5 | O5: =Rechner!$C$6*(1+Rechner!$C$32)^A5 | P5: =O5-I5
A6: 2 | B6: =IF(A6<=Rechner!$C$20,Rechner!$C$18,Rechner!$C$21) | C6: =I5 | D6: =Rechner!$H$7*12*(1+Rechner!$C$30)^(A6-1) | E6: =-D6*Rechner!$C$25 | F6: =(Rechner!$H$15+Rechner!$H$16)*12*(1+Rechner!$C$31)^(A6-1) | G6: =IF(C6<=0,0,IF(I6>0,-(12*(Rechner!$H$10*(Rechner!$C$18+Rechner!$C$19)/12)-(C6-I6)),IF(B6=0,0,-((Rechner!$H$10*(Rechner!$C$18+Rechner!$C$19)/12)*NPER(B6/12,-(Rechner!$H$10*(Rechner!$C$18+Rechner!$C$19)/12),C6)-C6)))) | H6: =-(C6-I6) | I6: =IF(C6<=0,0,IF(B6=0,MAX(0,C6-12*(Rechner!$H$10*(Rechner!$C$18+Rechner!$C$19)/12)),MAX(0,(C6*(1+B6/12)^12-(Rechner!$H$10*(Rechner!$C$18+Rechner!$C$19)/12)*((1+B6/12)^12-1)/(B6/12))))) | J6: =D6+E6+F6+G6+H6 | K6: =-Rechner!$H$28*(A6<=1/Rechner!$C$27) | L6: =-(D6+E6+F6+G6+K6)*Rechner!$C$28 | M6: =J6+L6 | N6: =N5+M6 | O6: =Rechner!$C$6*(1+Rechner!$C$32)^A6 | P6: =O6-I6
A7: 3 | B7: =IF(A7<=Rechner!$C$20,Rechner!$C$18,Rechner!$C$21) | C7: =I6 | D7: =Rechner!$H$7*12*(1+Rechner!$C$30)^(A7-1) | E7: =-D7*Rechner!$C$25 | F7: =(Rechner!$H$15+Rechner!$H$16)*12*(1+Rechner!$C$31)^(A7-1) | G7: =IF(C7<=0,0,IF(I7>0,-(12*(Rechner!$H$10*(Rechner!$C$18+Rechner!$C$19)/12)-(C7-I7)),IF(B7=0,0,-((Rechner!$H$10*(Rechner!$C$18+Rechner!$C$19)/12)*NPER(B7/12,-(Rechner!$H$10*(Rechner!$C$18+Rechner!$C$19)/12),C7)-C7)))) | H7: =-(C7-I7) | I7: =IF(C7<=0,0,IF(B7=0,MAX(0,C7-12*(Rechner!$H$10*(Rechner!$C$18+Rechner!$C$19)/12)),MAX(0,(C7*(1+B7/12)^12-(Rechner!$H$10*(Rechner!$C$18+Rechner!$C$19)/12)*((1+B7/12)^12-1)/(B7/12))))) | J7: =D7+E7+F7+G7+H7 | K7: =-Rechner!$H$28*(A7<=1/Rechner!$C$27) | L7: =-(D7+E7+F7+G7+K7)*Rechner!$C$28 | M7: =J7+L7 | N7: =N6+M7 | O7: =Rechner!$C$6*(1+Rechner!$C$32)^A7 | P7: =O7-I7
A8: 4 | B8: =IF(A8<=Rechner!$C$20,Rechner!$C$18,Rechner!$C$21) | C8: =I7 | D8: =Rechner!$H$7*12*(1+Rechner!$C$30)^(A8-1) | E8: =-D8*Rechner!$C$25 | F8: =(Rechner!$H$15+Rechner!$H$16)*12*(1+Rechner!$C$31)^(A8-1) | G8: =IF(C8<=0,0,IF(I8>0,-(12*(Rechner!$H$10*(Rechner!$C$18+Rechner!$C$19)/12)-(C8-I8)),IF(B8=0,0,-((Rechner!$H$10*(Rechner!$C$18+Rechner!$C$19)/12)*NPER(B8/12,-(Rechner!$H$10*(Rechner!$C$18+Rechner!$C$19)/12),C8)-C8)))) | H8: =-(C8-I8) | I8: =IF(C8<=0,0,IF(B8=0,MAX(0,C8-12*(Rechner!$H$10*(Rechner!$C$18+Rechner!$C$19)/12)),MAX(0,(C8*(1+B8/12)^12-(Rechner!$H$10*(Rechner!$C$18+Rechner!$C$19)/12)*((1+B8/12)^12-1)/(B8/12))))) | J8: =D8+E8+F8+G8+H8 | K8: =-Rechner!$H$28*(A8<=1/Rechner!$C$27) | L8: =-(D8+E8+F8+G8+K8)*Rechner!$C$28 | M8: =J8+L8 | N8: =N7+M8 | O8: =Rechner!$C$6*(1+Rechner!$C$32)^A8 | P8: =O8-I8
A9: 5 | B9: =IF(A9<=Rechner!$C$20,Rechner!$C$18,Rechner!$C$21) | C9: =I8 | D9: =Rechner!$H$7*12*(1+Rechner!$C$30)^(A9-1) | E9: =-D9*Rechner!$C$25 | F9: =(Rechner!$H$15+Rechner!$H$16)*12*(1+Rechner!$C$31)^(A9-1) | G9: =IF(C9<=0,0,IF(I9>0,-(12*(Rechner!$H$10*(Rechner!$C$18+Rechner!$C$19)/12)-(C9-I9)),IF(B9=0,0,-((Rechner!$H$10*(Rechner!$C$18+Rechner!$C$19)/12)*NPER(B9/12,-(Rechner!$H$10*(Rechner!$C$18+Rechner!$C$19)/12),C9)-C9)))) | H9: =-(C9-I9) | I9: =IF(C9<=0,0,IF(B9=0,MAX(0,C9-12*(Rechner!$H$10*(Rechner!$C$18+Rechner!$C$19)/12)),MAX(0,(C9*(1+B9/12)^12-(Rechner!$H$10*(Rechner!$C$18+Rechner!$C$19)/12)*((1+B9/12)^12-1)/(B9/12))))) | J9: =D9+E9+F9+G9+H9 | K9: =-Rechner!$H$28*(A9<=1/Rechner!$C$27) | L9: =-(D9+E9+F9+G9+K9)*Rechner!$C$28 | M9: =J9+L9 | N9: =N8+M9 | O9: =Rechner!$C$6*(1+Rechner!$C$32)^A9 | P9: =O9-I9
A10: 6 | B10: =IF(A10<=Rechner!$C$20,Rechner!$C$18,Rechner!$C$21) | C10: =I9 | D10: =Rechner!$H$7*12*(1+Rechner!$C$30)^(A10-1) | E10: =-D10*Rechner!$C$25 | F10: =(Rechner!$H$15+Rechner!$H$16)*12*(1+Rechner!$C$31)^(A10-1) | G10: =IF(C10<=0,0,IF(I10>0,-(12*(Rechner!$H$10*(Rechner!$C$18+Rechner!$C$19)/12)-(C10-I10)),IF(B10=0,0,-((Rechner!$H$10*(Rechner!$C$18+Rechner!$C$19)/12)*NPER(B10/12,-(Rechner!$H$10*(Rechner!$C$18+Rechner!$C$19)/12),C10)-C10)))) | H10: =-(C10-I10) | I10: =IF(C10<=0,0,IF(B10=0,MAX(0,C10-12*(Rechner!$H$10*(Rechner!$C$18+Rechner!$C$19)/12)),MAX(0,(C10*(1+B10/12)^12-(Rechner!$H$10*(Rechner!$C$18+Rechner!$C$19)/12)*((1+B10/12)^12-1)/(B10/12))))) | J10: =D10+E10+F10+G10+H10 | K10: =-Rechner!$H$28*(A10<=1/Rechner!$C$27) | L10: =-(D10+E10+F10+G10+K10)*Rechner!$C$28 | M10: =J10+L10 | N10: =N9+M10 | O10: =Rechner!$C$6*(1+Rechner!$C$32)^A10 | P10: =O10-I10
A11: 7 | B11: =IF(A11<=Rechner!$C$20,Rechner!$C$18,Rechner!$C$21) | C11: =I10 | D11: =Rechner!$H$7*12*(1+Rechner!$C$30)^(A11-1) | E11: =-D11*Rechner!$C$25 | F11: =(Rechner!$H$15+Rechner!$H$16)*12*(1+Rechner!$C$31)^(A11-1) | G11: =IF(C11<=0,0,IF(I11>0,-(12*(Rechner!$H$10*(Rechner!$C$18+Rechner!$C$19)/12)-(C11-I11)),IF(B11=0,0,-((Rechner!$H$10*(Rechner!$C$18+Rechner!$C$19)/12)*NPER(B11/12,-(Rechner!$H$10*(Rechner!$C$18+Rechner!$C$19)/12),C11)-C11)))) | H11: =-(C11-I11) | I11: =IF(C11<=0,0,IF(B11=0,MAX(0,C11-12*(Rechner!$H$10*(Rechner!$C$18+Rechner!$C$19)/12)),MAX(0,(C11*(1+B11/12)^12-(Rechner!$H$10*(Rechner!$C$18+Rechner!$C$19)/12)*((1+B11/12)^12-1)/(B11/12))))) | J11: =D11+E11+F11+G11+H11 | K11: =-Rechner!$H$28*(A11<=1/Rechner!$C$27) | L11: =-(D11+E11+F11+G11+K11)*Rechner!$C$28 | M11: =J11+L11 | N11: =N10+M11 | O11: =Rechner!$C$6*(1+Rechner!$C$32)^A11 | P11: =O11-I11
A12: 8 | B12: =IF(A12<=Rechner!$C$20,Rechner!$C$18,Rechner!$C$21) | C12: =I11 | D12: =Rechner!$H$7*12*(1+Rechner!$C$30)^(A12-1) | E12: =-D12*Rechner!$C$25 | F12: =(Rechner!$H$15+Rechner!$H$16)*12*(1+Rechner!$C$31)^(A12-1) | G12: =IF(C12<=0,0,IF(I12>0,-(12*(Rechner!$H$10*(Rechner!$C$18+Rechner!$C$19)/12)-(C12-I12)),IF(B12=0,0,-((Rechner!$H$10*(Rechner!$C$18+Rechner!$C$19)/12)*NPER(B12/12,-(Rechner!$H$10*(Rechner!$C$18+Rechner!$C$19)/12),C12)-C12)))) | H12: =-(C12-I12) | I12: =IF(C12<=0,0,IF(B12=0,MAX(0,C12-12*(Rechner!$H$10*(Rechner!$C$18+Rechner!$C$19)/12)),MAX(0,(C12*(1+B12/12)^12-(Rechner!$H$10*(Rechner!$C$18+Rechner!$C$19)/12)*((1+B12/12)^12-1)/(B12/12))))) | J12: =D12+E12+F12+G12+H12 | K12: =-Rechner!$H$28*(A12<=1/Rechner!$C$27) | L12: =-(D12+E12+F12+G12+K12)*Rechner!$C$28 | M12: =J12+L12 | N12: =N11+M12 | O12: =Rechner!$C$6*(1+Rechner!$C$32)^A12 | P12: =O12-I12
A13: 9 | B13: =IF(A13<=Rechner!$C$20,Rechner!$C$18,Rechner!$C$21) | C13: =I12 | D13: =Rechner!$H$7*12*(1+Rechner!$C$30)^(A13-1) | E13: =-D13*Rechner!$C$25 | F13: =(Rechner!$H$15+Rechner!$H$16)*12*(1+Rechner!$C$31)^(A13-1) | G13: =IF(C13<=0,0,IF(I13>0,-(12*(Rechner!$H$10*(Rechner!$C$18+Rechner!$C$19)/12)-(C13-I13)),IF(B13=0,0,-((Rechner!$H$10*(Rechner!$C$18+Rechner!$C$19)/12)*NPER(B13/12,-(Rechner!$H$10*(Rechner!$C$18+Rechner!$C$19)/12),C13)-C13)))) | H13: =-(C13-I13) | I13: =IF(C13<=0,0,IF(B13=0,MAX(0,C13-12*(Rechner!$H$10*(Rechner!$C$18+Rechner!$C$19)/12)),MAX(0,(C13*(1+B13/12)^12-(Rechner!$H$10*(Rechner!$C$18+Rechner!$C$19)/12)*((1+B13/12)^12-1)/(B13/12))))) | J13: =D13+E13+F13+G13+H13 | K13: =-Rechner!$H$28*(A13<=1/Rechner!$C$27) | L13: =-(D13+E13+F13+G13+K13)*Rechner!$C$28 | M13: =J13+L13 | N13: =N12+M13 | O13: =Rechner!$C$6*(1+Rechner!$C$32)^A13 | P13: =O13-I13
A14: 10 | B14: =IF(A14<=Rechner!$C$20,Rechner!$C$18,Rechner!$C$21) | C14: =I13 | D14: =Rechner!$H$7*12*(1+Rechner!$C$30)^(A14-1) | E14: =-D14*Rechner!$C$25 | F14: =(Rechner!$H$15+Rechner!$H$16)*12*(1+Rechner!$C$31)^(A14-1) | G14: =IF(C14<=0,0,IF(I14>0,-(12*(Rechner!$H$10*(Rechner!$C$18+Rechner!$C$19)/12)-(C14-I14)),IF(B14=0,0,-((Rechner!$H$10*(Rechner!$C$18+Rechner!$C$19)/12)*NPER(B14/12,-(Rechner!$H$10*(Rechner!$C$18+Rechner!$C$19)/12),C14)-C14)))) | H14: =-(C14-I14) | I14: =IF(C14<=0,0,IF(B14=0,MAX(0,C14-12*(Rechner!$H$10*(Rechner!$C$18+Rechner!$C$19)/12)),MAX(0,(C14*(1+B14/12)^12-(Rechner!$H$10*(Rechner!$C$18+Rechner!$C$19)/12)*((1+B14/12)^12-1)/(B14/12))))) | J14: =D14+E14+F14+G14+H14 | K14: =-Rechner!$H$28*(A14<=1/Rechner!$C$27) | L14: =-(D14+E14+F14+G14+K14)*Rechner!$C$28 | M14: =J14+L14 | N14: =N13+M14 | O14: =Rechner!$C$6*(1+Rechner!$C$32)^A14 | P14: =O14-I14
A15: 11 | B15: =IF(A15<=Rechner!$C$20,Rechner!$C$18,Rechner!$C$21) | C15: =I14 | D15: =Rechner!$H$7*12*(1+Rechner!$C$30)^(A15-1) | E15: =-D15*Rechner!$C$25 | F15: =(Rechner!$H$15+Rechner!$H$16)*12*(1+Rechner!$C$31)^(A15-1) | G15: =IF(C15<=0,0,IF(I15>0,-(12*(Rechner!$H$10*(Rechner!$C$18+Rechner!$C$19)/12)-(C15-I15)),IF(B15=0,0,-((Rechner!$H$10*(Rechner!$C$18+Rechner!$C$19)/12)*NPER(B15/12,-(Rechner!$H$10*(Rechner!$C$18+Rechner!$C$19)/12),C15)-C15)))) | H15: =-(C15-I15) | I15: =IF(C15<=0,0,IF(B15=0,MAX(0,C15-12*(Rechner!$H$10*(Rechner!$C$18+Rechner!$C$19)/12)),MAX(0,(C15*(1+B15/12)^12-(Rechner!$H$10*(Rechner!$C$18+Rechner!$C$19)/12)*((1+B15/12)^12-1)/(B15/12))))) | J15: =D15+E15+F15+G15+H15 | K15: =-Rechner!$H$28*(A15<=1/Rechner!$C$27) | L15: =-(D15+E15+F15+G15+K15)*Rechner!$C$28 | M15: =J15+L15 | N15: =N14+M15 | O15: =Rechner!$C$6*(1+Rechner!$C$32)^A15 | P15: =O15-I15
A16: 12 | B16: =IF(A16<=Rechner!$C$20,Rechner!$C$18,Rechner!$C$21) | C16: =I15 | D16: =Rechner!$H$7*12*(1+Rechner!$C$30)^(A16-1) | E16: =-D16*Rechner!$C$25 | F16: =(Rechner!$H$15+Rechner!$H$16)*12*(1+Rechner!$C$31)^(A16-1) | G16: =IF(C16<=0,0,IF(I16>0,-(12*(Rechner!$H$10*(Rechner!$C$18+Rechner!$C$19)/12)-(C16-I16)),IF(B16=0,0,-((Rechner!$H$10*(Rechner!$C$18+Rechner!$C$19)/12)*NPER(B16/12,-(Rechner!$H$10*(Rechner!$C$18+Rechner!$C$19)/12),C16)-C16)))) | H16: =-(C16-I16) | I16: =IF(C16<=0,0,IF(B16=0,MAX(0,C16-12*(Rechner!$H$10*(Rechner!$C$18+Rechner!$C$19)/12)),MAX(0,(C16*(1+B16/12)^12-(Rechner!$H$10*(Rechner!$C$18+Rechner!$C$19)/12)*((1+B16/12)^12-1)/(B16/12))))) | J16: =D16+E16+F16+G16+H16 | K16: =-Rechner!$H$28*(A16<=1/Rechner!$C$27) | L16: =-(D16+E16+F16+G16+K16)*Rechner!$C$28 | M16: =J16+L16 | N16: =N15+M16 | O16: =Rechner!$C$6*(1+Rechner!$C$32)^A16 | P16: =O16-I16
A17: 13 | B17: =IF(A17<=Rechner!$C$20,Rechner!$C$18,Rechner!$C$21) | C17: =I16 | D17: =Rechner!$H$7*12*(1+Rechner!$C$30)^(A17-1) | E17: =-D17*Rechner!$C$25 | F17: =(Rechner!$H$15+Rechner!$H$16)*12*(1+Rechner!$C$31)^(A17-1) | G17: =IF(C17<=0,0,IF(I17>0,-(12*(Rechner!$H$10*(Rechner!$C$18+Rechner!$C$19)/12)-(C17-I17)),IF(B17=0,0,-((Rechner!$H$10*(Rechner!$C$18+Rechner!$C$19)/12)*NPER(B17/12,-(Rechner!$H$10*(Rechner!$C$18+Rechner!$C$19)/12),C17)-C17)))) | H17: =-(C17-I17) | I17: =IF(C17<=0,0,IF(B17=0,MAX(0,C17-12*(Rechner!$H$10*(Rechner!$C$18+Rechner!$C$19)/12)),MAX(0,(C17*(1+B17/12)^12-(Rechner!$H$10*(Rechner!$C$18+Rechner!$C$19)/12)*((1+B17/12)^12-1)/(B17/12))))) | J17: =D17+E17+F17+G17+H17 | K17: =-Rechner!$H$28*(A17<=1/Rechner!$C$27) | L17: =-(D17+E17+F17+G17+K17)*Rechner!$C$28 | M17: =J17+L17 | N17: =N16+M17 | O17: =Rechner!$C$6*(1+Rechner!$C$32)^A17 | P17: =O17-I17
... A34: 30 | B34: =IF(A34<=Rechner!$C$20,Rechner!$C$18,Rechner!$C$21) | C34: =I33 | D34: =Rechner!$H$7*12*(1+Rechner!$C$30)^(A34-1) | E34: =-D34*Rechner!$C$25 | F34: =(Rechner!$H$15+Rechner!$H$16)*12*(1+Rechner!$C$31)^(A34-1) | G34: =IF(C34<=0,0,IF(I34>0,-(12*(Rechner!$H$10*(Rechner!$C$18+Rechner!$C$19)/12)-(C34-I34)),IF(B34=0,0,-((Rechner!$H$10*(Rechner!$C$18+Rechner!$C$19)/12)*NPER(B34/12,-(Rechner!$H$10*(Rechner!$C$18+Rechner!$C$19)/12),C34)-C34)))) | H34: =-(C34-I34) | I34: =IF(C34<=0,0,IF(B34=0,MAX(0,C34-12*(Rechner!$H$10*(Rechner!$C$18+Rechner!$C$19)/12)),MAX(0,(C34*(1+B34/12)^12-(Rechner!$H$10*(Rechner!$C$18+Rechner!$C$19)/12)*((1+B34/12)^12-1)/(B34/12))))) | J34: =D34+E34+F34+G34+H34 | K34: =-Rechner!$H$28*(A34<=1/Rechner!$C$27) | L34: =-(D34+E34+F34+G34+K34)*Rechner!$C$28 | M34: =J34+L34 | N34: =N33+M34 | O34: =Rechner!$C$6*(1+Rechner!$C$32)^A34 | P34: =O34-I34
A36: Beige hinterlegter Zinssatz = nach Ende der Zinsbindung (Anschlusszins). Jahr 1 entspricht dem Monatswert im Rechner × 12.

Sheet Lebenserwartung
A1: Fernere Lebenserwartung (Frauen, gerundet)
A2: Quelle: Statistisches Bundesamt (Destatis), Sterbetafel 2021/23, gerundete Näherungswerte. Frauenwert = vorsichtige (längere) Annahme.
A3: Alter | B3: Weitere Lebensjahre
A4: 60 | B4: 25
A5: 65 | B5: 20.9
A6: 70 | B6: 16.9
A7: 75 | B7: 13.2
A8: 80 | B8: 9.8
A9: 85 | B9: 6.9
A10: 90 | B10: 4.6
A11: 95 | B11: 3
